<?xml version="1.0" encoding="utf-8"?>
<!-- This URDF was automatically created by SolidWorks to URDF Exporter! Originally created by Stephen Brawner (brawner@gmail.com) 
     Commit Version: 1.6.0-4-g7f85cfe  Build Version: 1.6.7995.38578
     For more information, please see http://wiki.ros.org/sw_urdf_exporter -->
<robot
  name="AR4_robotv5">
  <link
    name="fixed_base">
    <inertial>
      <origin
        xyz="-0.0306536963899715 -2.44484649533754E-16 0.0159301721557005"
        rpy="0 0 0" />
      <mass
        value="0.430596742452915" />
      <inertia
        ixx="0.000592836541089023"
        ixy="-2.7947074339812E-18"
        ixz="3.16649003573555E-06"
        iyy="0.00143993470886868"
        iyz="-1.46147455512225E-18"
        izz="0.00196041354174175" />
    </inertial>
    <visual>
      <origin
        xyz="0 0 0"
        rpy="0 0 0" />
      <geometry>
        <mesh
          filename="package://AR4_robotv5/meshes/fixed_base.STL" />
      </geometry>
      <material
        name="">
        <color
          rgba="0.792156862745098 0.819607843137255 0.933333333333333 1" />
      </material>
    </visual>
    <collision>
      <origin
        xyz="0 0 0"
        rpy="0 0 0" />
      <geometry>
        <mesh
          filename="package://AR4_robotv5/meshes/fixed_base.STL" />
      </geometry>
    </collision>
  </link>
  <link
    name="link1">
    <inertial>
      <origin
        xyz="-0.0323300202262942 0.0876379666323026 0.00606618776675665"
        rpy="0 0 0" />
      <mass
        value="0.511108316154896" />
      <inertia
        ixx="0.000444689420884809"
        ixy="3.3051231296309E-05"
        ixz="-3.59204112024893E-06"
        iyy="0.000393019588638468"
        iyz="2.35566156473204E-06"
        izz="0.00061675346116437" />
    </inertial>
    <visual>
      <origin
        xyz="0 0 0"
        rpy="0 0 0" />
      <geometry>
        <mesh
          filename="package://AR4_robotv5/meshes/link1.STL" />
      </geometry>
      <material
        name="">
        <color
          rgba="0.792156862745098 0.819607843137255 0.933333333333333 1" />
      </material>
    </visual>
    <collision>
      <origin
        xyz="0 0 0"
        rpy="0 0 0" />
      <geometry>
        <mesh
          filename="package://AR4_robotv5/meshes/link1.STL" />
      </geometry>
    </collision>
  </link>
  <joint
    name="j1"
    type="revolute">
    <origin
      xyz="0 0 0"
      rpy="1.5708 0 -3.1416" />
    <parent
      link="fixed_base" />
    <child
      link="link1" />
    <axis
      xyz="0 1 0" />
    <limit
      lower="-2.967"
      upper="2.967"
      effort="0"
      velocity="0" />
  </joint>
  <link
    name="link2">
    <inertial>
      <origin
        xyz="0.116556714204464 -0.000883910513608144 0.046618699592506"
        rpy="0 0 0" />
      <mass
        value="0.323855620699725" />
      <inertia
        ixx="0.000133908814758313"
        ixy="2.65151242326013E-07"
        ixz="-2.32664150337736E-08"
        iyy="0.00230480430533661"
        iyz="-2.16182715850116E-09"
        izz="0.00240195674477352" />
    </inertial>
    <visual>
      <origin
        xyz="0 0 0"
        rpy="0 0 0" />
      <geometry>
        <mesh
          filename="package://AR4_robotv5/meshes/link2.STL" />
      </geometry>
      <material
        name="">
        <color
          rgba="0.792156862745098 0.819607843137255 0.933333333333333 1" />
      </material>
    </visual>
    <collision>
      <origin
        xyz="0 0 0"
        rpy="0 0 0" />
      <geometry>
        <mesh
          filename="package://AR4_robotv5/meshes/link2.STL" />
      </geometry>
    </collision>
  </link>
  <joint
    name="j2"
    type="revolute">
    <origin
      xyz="-0.0641992596263865 0.151269000000001 0"
      rpy="0 0 1.5707963267949" />
    <parent
      link="link1" />
    <child
      link="link2" />
    <axis
      xyz="0 0 1" />
    <limit
      lower="-0.733"
      upper="1.571"
      effort="0"
      velocity="0" />
  </joint>
  <link
    name="link3">
    <inertial>
      <origin
        xyz="3.34736758973997E-05 -0.014678986348043 0.00415412090811089"
        rpy="0 0 0" />
      <mass
        value="0.0851867148181061" />
      <inertia
        ixx="3.47805591735004E-05"
        ixy="-2.65949151380486E-08"
        ixz="-2.59618294046106E-08"
        iyy="3.59173363820087E-05"
        iyz="-3.28353176410664E-07"
        izz="3.06202603811511E-05" />
    </inertial>
    <visual>
      <origin
        xyz="0 0 0"
        rpy="0 0 0" />
      <geometry>
        <mesh
          filename="package://AR4_robotv5/meshes/link3.STL" />
      </geometry>
      <material
        name="">
        <color
          rgba="0.792156862745098 0.819607843137255 0.933333333333333 1" />
      </material>
    </visual>
    <collision>
      <origin
        xyz="0 0 0"
        rpy="0 0 0" />
      <geometry>
        <mesh
          filename="package://AR4_robotv5/meshes/link3.STL" />
      </geometry>
    </collision>
  </link>
  <joint
    name="j3"
    type="revolute">
    <origin
      xyz="0.304999999999999 0 0"
      rpy="-1.5707963267949 0 0" />
    <parent
      link="link2" />
    <child
      link="link3" />
    <axis
      xyz="0 1 0" />
    <limit
      lower="-1.553"
      upper="0.908"
      effort="0"
      velocity="0" />
  </joint>
  <link
    name="link4">
    <inertial>
      <origin
        xyz="1.65972746341003E-06 0.114308868744708 -0.00196391551724488"
        rpy="0 0 0" />
      <mass
        value="0.330915774998875" />
      <inertia
        ixx="0.000770714464836303"
        ixy="-5.83780279549621E-08"
        ixz="-9.03681380466358E-09"
        iyy="0.000143595801102121"
        iyz="6.92144604392256E-05"
        izz="0.00078144566914053" />
    </inertial>
    <visual>
      <origin
        xyz="0 0 0"
        rpy="0 0 0" />
      <geometry>
        <mesh
          filename="package://AR4_robotv5/meshes/link4.STL" />
      </geometry>
      <material
        name="">
        <color
          rgba="0.792156862745098 0.819607843137255 0.933333333333333 1" />
      </material>
    </visual>
    <collision>
      <origin
        xyz="0 0 0"
        rpy="0 0 0" />
      <geometry>
        <mesh
          filename="package://AR4_robotv5/meshes/link4.STL" />
      </geometry>
    </collision>
  </link>
  <joint
    name="j4"
    type="revolute">
    <origin
      xyz="0 0.00165000000000398 0"
      rpy="1.57079632679489 0 0.000843332253807779" />
    <parent
      link="link3" />
    <child
      link="link4" />
    <axis
      xyz="0 1 0" />
    <limit
      lower="-2.88"
      upper="2.88"
      effort="0"
      velocity="0" />
  </joint>
  <link
    name="link5">
    <inertial>
      <origin
        xyz="4.46631409203313E-05 0.0010582355958296 -0.000637441503684444"
        rpy="0 0 0" />
      <mass
        value="0.0245034490928621" />
      <inertia
        ixx="9.03633668429963E-06"
        ixy="9.04257798543254E-09"
        ixz="-2.14953206266449E-09"
        iyy="5.7526255063883E-06"
        iyz="-2.03350961333318E-08"
        izz="1.2157538793257E-05" />
    </inertial>
    <visual>
      <origin
        xyz="0 0 0"
        rpy="0 0 0" />
      <geometry>
        <mesh
          filename="package://AR4_robotv5/meshes/link5.STL" />
      </geometry>
      <material
        name="">
        <color
          rgba="0.792156862745098 0.819607843137255 0.933333333333333 1" />
      </material>
    </visual>
    <collision>
      <origin
        xyz="0 0 0"
        rpy="0 0 0" />
      <geometry>
        <mesh
          filename="package://AR4_robotv5/meshes/link5.STL" />
      </geometry>
    </collision>
  </link>
  <joint
    name="j5"
    type="revolute">
    <origin
      xyz="0 0.225041312909753 0.0007499997333115"
      rpy="1.57079631189374 -0.000843332253807779 0" />
    <parent
      link="link4" />
    <child
      link="link5" />
    <axis
      xyz="0 1 0" />
    <limit
      lower="-1.833"
      upper="1.833"
      effort="0"
      velocity="0" />
  </joint>
  <link
    name="link6">
    <inertial>
      <origin
        xyz="-0.00160633858276565 -0.000457062617008543 -0.0587695487539506"
        rpy="0 0 0" />
      <mass
        value="0.121376042767568" />
      <inertia
        ixx="3.53039178237827E-05"
        ixy="-4.7308746638171E-08"
        ixz="-4.47726039625278E-07"
        iyy="1.81330403322111E-05"
        iyz="-2.21518225549172E-07"
        izz="4.26315107565952E-05" />
    </inertial>
    <visual>
      <origin
        xyz="0 0 0"
        rpy="0 0 0" />
      <geometry>
        <mesh
          filename="package://AR4_robotv5/meshes/link6.STL" />
      </geometry>
      <material
        name="">
        <color
          rgba="0.792156862745098 0.819607843137255 0.933333333333333 1" />
      </material>
    </visual>
    <collision>
      <origin
        xyz="0 0 0"
        rpy="0 0 0" />
      <geometry>
        <mesh
          filename="package://AR4_robotv5/meshes/link6.STL" />
      </geometry>
    </collision>
  </link>
  <joint
    name="j6"
    type="revolute">
    <origin
      xyz="0 0 0"
      rpy="0 0 3.14159265358979" />
    <parent
      link="link5" />
    <child
      link="link6" />
    <axis
      xyz="0 0 1" />
    <limit
      lower="-2.705"
      upper="2.705"
      effort="0"
      velocity="0" />
  </joint>
  <link
    name="link7">
    <inertial>
      <origin
        xyz="0.00401715386268953 -1.82145964977565E-17 -1.11022302462516E-16"
        rpy="0 0 0" />
      <mass
        value="4.28541445828409E-05" />
      <inertia
        ixx="3.26374304335892E-11"
        ixy="1.38439272082023E-24"
        ixz="4.70953291237086E-24"
        iyy="3.40574299802589E-10"
        iyz="2.22599419002211E-28"
        izz="3.40574299802589E-10" />
    </inertial>
    <visual>
      <origin
        xyz="0 0 0"
        rpy="0 0 0" />
      <geometry>
        <mesh
          filename="package://AR4_robotv5/meshes/link7.STL" />
      </geometry>
      <material
        name="">
        <color
          rgba="0.792156862745098 0.819607843137255 0.933333333333333 1" />
      </material>
    </visual>
    <collision>
      <origin
        xyz="0 0 0"
        rpy="0 0 0" />
      <geometry>
        <mesh
          filename="package://AR4_robotv5/meshes/link7.STL" />
      </geometry>
    </collision>
  </link>
  <joint
    name="j7"
    type="fixed">
    <origin
      xyz="0 -0.000201201957805657 -0.0848321039170631"
      rpy="0 1.5707963267949 0" />
    <parent
      link="link6" />
    <child
      link="link7" />
    <axis
      xyz="0 0 0" />
  </joint>
</robot>